Workbook
Name BASE_DE_DATOS: #REF!
Name DATOS_CLAE: #REF!
Name DATOS_CLAE_CLAEDESC: '[1]privado act econ'!$A$2:$A$773
Name DATOS_CLAE_EDAD: '[1]privado act econ'!$C$2:$C$773
Name DATOS_CLAE_PERSONAS: '[1]privado act econ'!$D$2:$D$773
Name DATOS_CLAE_REM2: '[1]privado act econ'!$E$2:$E$773
Name DATOS_CLAE_SEXO: '[1]privado act econ'!$B$2:$B$773
Name DATOS_DOC_PROVINCIAS: #REF!
Name DATOS_DOC_PROVINCIAS_DOC_PROV: #REF!
Name DATOS_DOC_PROVINCIAS_EDAD: #REF!
Name DATOS_DOC_PROVINCIAS_PERSONAS: #REF!
Name DATOS_DOC_PROVINCIAS_REM2: #REF!
Name DATOS_DOC_PROVINCIAS_SEXO: #REF!
Name DATOS_PROVINCIAS: #REF!
Name DATOS_PROVINCIAS_EDAD: '[1]Público pcial'!$C$2:$C$884
Name DATOS_PROVINCIAS_PERSONAS: '[1]Público pcial'!$D$2:$D$884
Name DATOS_PROVINCIAS_PROV: '[1]Público pcial'!$A$2:$A$884
Name DATOS_PROVINCIAS_REM2: '[1]Público pcial'!$E$2:$E$884
Name DATOS_PROVINCIAS_SEXO: '[1]Público pcial'!$B$2:$B$884
Name DATOS_RREE: #REF!
Name DATOS_RREE_EDAD: #REF!
Name DATOS_RREE_PERSONAS: #REF!
Name datos_rree_personas2: #REF!
Name DATOS_RREE_REM2: #REF!
Name DATOS_RREE_SECTOR: #REF!
Name DATOS_RREE_SEXO: #REF!
Name INVA_ESP_2017: '[2]altas 4 (especiales)'!$B$129
Name INVA_ESP_2018: '[2]altas 4 (especiales)'!$B$67
Name INVA_ESP_2019: '[2]altas 4 (especiales)'!$B$6
Name INVA_ESP_2020: '[3]altas 4 (especiales)'!$B$6
Name INVA_ESP_2021: '[4]altas 4 (especiales)'!$B$6
Name INVA_ESP_2022: '[5]altas 4 (especiales)'!$B$6
Name INVA_ESP_2023: '[6]altas 4 (especiales)'!$B$6

Sheet historial_ratios
A1: anio | B1: RS | C1: RL
A2: {=+TRANSPOSE('[7]NDC_10-25_morat'!N1:Q1)} -> 2022 | B2: {=+TRANSPOSE('[7]NDC_10-25_morat'!N49:Q49)} -> 1.2998199 | C2: {=+TRANSPOSE('[7]NDC_10-25_morat'!N50:Q50)} -> 0.96622668
A3: 2023 | B3: 0.99538069 | C3: 0.72902523
A4: 2024 | B4: 1.2417484 | C4: 0.92224536
A5: 2025 | B5: 1.5663106 | C5: 1.1511806

Sheet constantes
A1: variable | B1: valor | C1: INDICE
A2: prop_trabajadores | B2: =+'[7]NDC_10-25_morat'!S11 -> 0.6569162
A3: alcance | B3: =+'[7]NDC_10-25_morat'!S15 -> 0.84066971
A4: prop_pensionados | B4: =+'[7]NDC_10-25_morat'!S23 -> 0.035520399
A5: prop_pensionados_menores | B5: =+'[7]NDC_10-25_morat'!B60 -> 0.18234941
A6: propor_pen_morat | B6: =+'[7]NDC_10-25_morat'!S24 -> 0.20660613
A7: propor_jub_morat | B7: =+'[7]NDC_10-25_morat'!S16 -> 0.62919166
A8: desc_pen_morat | B8: =+'[7]NDC_10-25_morat'!B62 -> -0.78529601
A9: desc_jub_morat | B9: =+'[7]NDC_10-25_morat'!B61 -> -0.44399456
A10: a_jubilados | B10: =+'[7]NDC_10-25_morat'!B64 -> 12.939231
A11: a_pensionados | B11: =+'[7]NDC_10-25_morat'!B63 -> 21.348257
A12: TD | B12: 30
A13: i_nocional_0 | B13: 0.0125
A14: i_fondo | B14: 0.0125
A15: fondo_reserva_0 | B15: =+'[7]NDC_10-25_morat'!Q43 -> 1.2843935e+14
A16: aporte_NDC_mensual | B16: =+[7]ndc_jub_sim!Q20 -> 296699.47
A17: informalidad_0 | B17: =+'[7]NDC_10-25'!S7 -> 0.417125
A18: a_jub_extensible | B18: =+[7]ndc_jub_sim!B31 -> 18.933799
A19: sueldo_neto | B19: =+(B16/(0.11+0.17))*(1-0.11-0.03-0.03) -> 879502
A20: fondo_individuo_2025 | B20: =+[7]ndc_jub_sim!Q24 -> 65217207
A21: fondo_arg_prom | B21: =+[7]ndc_jub_sim!J24 -> 37341883
A22: edad_prom_aportante | B22: =+[7]edad_aportantes!H4 -> 41.342032

Sheet proyeccion_pob
A1: Edad | B1: 2026 | C1: 2027 | D1: 2028 | E1: 2029 | F1: 2030 | G1: 2031 | H1: 2032 | I1: 2033 | J1: 2034 | K1: 2035 | L1: 2036 | M1: 2037 | N1: 2038 | O1: 2039 | P1: 2040 | Q1: INDICE
A2: 0 | B2: 460681.4 | C2: 446742.4 | D2: 437886.8 | E2: 432876.8 | F2: 430383 | G2: 430856.8 | H2: 433946.2 | I2: 438833.2 | J2: 444838.8 | K2: 451344.6 | L2: 457656.2 | M2: 463569.4 | N2: 468868.8 | O2: 473348 | P2: 476834
A3: 1 | B3: 460681.4 | C3: 446742.4 | D3: 437886.8 | E3: 432876.8 | F3: 430383 | G3: 430856.8 | H3: 433946.2 | I3: 438833.2 | J3: 444838.8 | K3: 451344.6 | L3: 457656.2 | M3: 463569.4 | N3: 468868.8 | O3: 473348 | P3: 476834
A4: 2 | B4: 460681.4 | C4: 446742.4 | D4: 437886.8 | E4: 432876.8 | F4: 430383 | G4: 430856.8 | H4: 433946.2 | I4: 438833.2 | J4: 444838.8 | K4: 451344.6 | L4: 457656.2 | M4: 463569.4 | N4: 468868.8 | O4: 473348 | P4: 476834
A5: 3 | B5: 460681.4 | C5: 446742.4 | D5: 437886.8 | E5: 432876.8 | F5: 430383 | G5: 430856.8 | H5: 433946.2 | I5: 438833.2 | J5: 444838.8 | K5: 451344.6 | L5: 457656.2 | M5: 463569.4 | N5: 468868.8 | O5: 473348 | P5: 476834
A6: 4 | B6: 460681.4 | C6: 446742.4 | D6: 437886.8 | E6: 432876.8 | F6: 430383 | G6: 430856.8 | H6: 433946.2 | I6: 438833.2 | J6: 444838.8 | K6: 451344.6 | L6: 457656.2 | M6: 463569.4 | N6: 468868.8 | O6: 473348 | P6: 476834
A7: 5 | B7: 629855.6 | C7: 588340.2 | D7: 545385.4 | E7: 507299.8 | F7: 480310.8 | G7: 461608.6 | H7: 447656.8 | I7: 438757.6 | J7: 433687 | K7: 431127.2 | L7: 431538.2 | M7: 434570.8 | N7: 439410.6 | O7: 445377.6 | P7: 451849.8
A8: 6 | B8: 629855.6 | C8: 588340.2 | D8: 545385.4 | E8: 507299.8 | F8: 480310.8 | G8: 461608.6 | H8: 447656.8 | I8: 438757.6 | J8: 433687 | K8: 431127.2 | L8: 431538.2 | M8: 434570.8 | N8: 439410.6 | O8: 445377.6 | P8: 451849.8
A9: 7 | B9: 629855.6 | C9: 588340.2 | D9: 545385.4 | E9: 507299.8 | F9: 480310.8 | G9: 461608.6 | H9: 447656.8 | I9: 438757.6 | J9: 433687 | K9: 431127.2 | L9: 431538.2 | M9: 434570.8 | N9: 439410.6 | O9: 445377.6 | P9: 451849.8
A10: 8 | B10: 629855.6 | C10: 588340.2 | D10: 545385.4 | E10: 507299.8 | F10: 480310.8 | G10: 461608.6 | H10: 447656.8 | I10: 438757.6 | J10: 433687 | K10: 431127.2 | L10: 431538.2 | M10: 434570.8 | N10: 439410.6 | O10: 445377.6 | P10: 451849.8
A11: 9 | B11: 629855.6 | C11: 588340.2 | D11: 545385.4 | E11: 507299.8 | F11: 480310.8 | G11: 461608.6 | H11: 447656.8 | I11: 438757.6 | J11: 433687 | K11: 431127.2 | L11: 431538.2 | M11: 434570.8 | N11: 439410.6 | O11: 445377.6 | P11: 451849.8
A12: 10 | B12: 756886.4 | C12: 748176.6 | D12: 734903 | E12: 709812.8 | F12: 672056.2 | G12: 630967.2 | H12: 589445 | I12: 546462.6 | J12: 508333.6 | K12: 481290.8 | L12: 462532.6 | M12: 448532.8 | N12: 439591.8 | O12: 434486.6 | P12: 431896.4
A13: 11 | B13: 756886.4 | C13: 748176.6 | D13: 734903 | E13: 709812.8 | F13: 672056.2 | G13: 630967.2 | H13: 589445 | I13: 546462.6 | J13: 508333.6 | K13: 481290.8 | L13: 462532.6 | M13: 448532.8 | N13: 439591.8 | O13: 434486.6 | P13: 431896.4
... A102: 100 | B102: 10217 | C102: 11367 | D102: 12654 | E102: 14049 | F102: 15478 | G102: 16756 | H102: 17842 | I102: 18735 | J102: 19276 | K102: 19720 | L102: 20298 | M102: 20936 | N102: 21610 | O102: 22335 | P102: 23133
A103: total_pob | B103: =SUM(B2:B102) -> 46466688 | C103: =SUM(C2:C102) -> 46540071 | D103: =SUM(D2:D102) -> 46609533 | E103: =SUM(E2:E102) -> 46676999 | F103: =SUM(F2:F102) -> 46744389 | G103: =SUM(G2:G102) -> 46814264 | H103: =SUM(H2:H102) -> 46886737 | I103: =SUM(I2:I102) -> 46961803 | ... P103: =SUM(P2:P102) -> 47514116
A104: activos | B104: =+SUM(B21:B66) -> 28334130 | C104: =+SUM(C21:C66) -> 28593757 | D104: =+SUM(D21:D66) -> 28861032 | E104: =+SUM(E21:E66) -> 29139313 | F104: =+SUM(F21:F66) -> 29415773 | G104: =+SUM(G21:G66) -> 29683894 | H104: =+SUM(H21:H66) -> 29939844 | I104: =+SUM(I21:I66) -> 30187462 | ... P104: =+SUM(P21:P66) -> 30992481
A105: pasivos | B105: =+SUM(B67:B102) -> 5922327 | C105: =+SUM(C67:C102) -> 6031328 | D105: =+SUM(D67:D102) -> 6142648 | E105: =+SUM(E67:E102) -> 6255112 | F105: =+SUM(F67:F102) -> 6367718 | G105: =+SUM(G67:G102) -> 6480544 | H105: =+SUM(H67:H102) -> 6594032 | I105: =+SUM(I67:I102) -> 6709837 | ... P105: =+SUM(P67:P102) -> 7789606

Sheet tabla_mort
A1: edad | B1: lx | C1: p(x;65-x) | D1: p(x;1) | G1: INDICE
A2: 20 | B2: 98556 | C2: 0.84676732 | D2: {=+[8]tabla_mort_raw!F59:F103} -> 0.99924991
A3: 21 | B3: 98482.074 | C3: 0.84740295 | D3: 0.99915979
A4: 22 | B4: 98399.328 | C4: 0.84811555 | D4: 0.99910576
A5: 23 | B5: 98311.336 | C5: 0.84887464 | D5: 0.99907528
A6: 24 | B6: 98220.425 | C6: 0.84966034 | D6: 0.999059
A7: 25 | B7: 98128 | C7: 0.85046062 | D7: 0.99905015
A8: 26 | B8: 98034.793 | C8: 0.8512692 | D8: 0.99904391
A9: 27 | B9: 97941.063 | C9: 0.85208387 | D9: 0.99903693
A10: 28 | B10: 97846.738 | C10: 0.85290528 | D10: 0.99902696
A11: 29 | B11: 97751.529 | C11: 0.85373601 | D11: 0.99901251
A12: 30 | B12: 97655 | C12: 0.8545799 | D12: 0.99899259
A13: 31 | B13: 97556.621 | C13: 0.85544168 | D13: 0.99896652
A14: 32 | B14: 97455.798 | C14: 0.85632668 | D14: 0.99893376
... A46: 64 | B46: 84658.803 | C46: 0.98576872 | D46: 0.98576872
A47: 65 | B47: 83454 | C47: 1
A48: 70 | B48: 75827
A49: 75 | B49: 65119
A50: 80 | B50: 51182
A51: 85 | B51: 35010
A52: 90 | B52: 19301
A53: 95 | B53: 7752
A54: 100 | B54: 2109

Sheet NDC_25-40_morat
A1: t | B1: 2010 | C1: 2011 | D1: 2012 | E1: 2013 | F1: 2014 | G1: 2015 | H1: 2016 | I1: 2017 | J1: 2018 | K1: 2019 | L1: 2020 | M1: 2021 | N1: 2022 | O1: 2023 | P1: 2024 | Q1: 2025 | R1: 2026 | S1: 2027 | T1: 2028 | U1: 2029 | V1: 2030 | W1: 2031 | X1: 2032 | Y1: 2033 | Z1: 2034 | AA1: 2035 | AB1: 2036 | AC1: 2037 | AD1: 2038 | AE1: 2039 | AF1: 2040
A2: total población | B2: =+HLOOKUP(B1,[7]proyeccion_pob!$A$1:$AF$103,103) -> 40788453 | C2: =+HLOOKUP(C1,[7]proyeccion_pob!$A$1:$AF$103,103) -> 41261490 | D2: =+HLOOKUP(D1,[7]proyeccion_pob!$A$1:$AF$103,103) -> 41733271 | E2: =+HLOOKUP(E1,[7]proyeccion_pob!$A$1:$AF$103,103) -> 42202935 | F2: =+HLOOKUP(F1,[7]proyeccion_pob!$A$1:$AF$103,103) -> 42669500 | G2: =+HLOOKUP(G1,[7]proyeccion_pob!$A$1:$AF$103,103) -> 43131966 | H2: =+HLOOKUP(H1,[7]proyeccion_pob!$A$1:$AF$103,103) -> 43590368 | I2: =+HLOOKUP(I1,[7]proyeccion_pob!$A$1:$AF$103,103) -> 44044811 | ... Q2: =+HLOOKUP(Q1,[7]proyeccion_pob!$A$1:$AF$103,103) -> 46387098 | R2: =+HLOOKUP(R$1,proyeccion_pob!$A$1:$AF$105,103) -> 46466688 | S2: =+HLOOKUP(S$1,proyeccion_pob!$A$1:$AF$105,103) -> 46540071 | T2: =+HLOOKUP(T$1,proyeccion_pob!$A$1:$AF$105,103) -> 46609533 | U2: =+HLOOKUP(U$1,proyeccion_pob!$A$1:$AF$105,103) -> 46676999 | V2: =+HLOOKUP(V$1,proyeccion_pob!$A$1:$AF$105,103) -> 46744389 | W2: =+HLOOKUP(W$1,proyeccion_pob!$A$1:$AF$105,103) -> 46814264 | X2: =+HLOOKUP(X$1,proyeccion_pob!$A$1:$AF$105,103) -> 46886737 | Y2: =+HLOOKUP(Y$1,proyeccion_pob!$A$1:$AF$105,103) -> 46961803 | ... AF2: =+HLOOKUP(AF$1,proyeccion_pob!$A$1:$AF$105,103) -> 47514116
A3: pasivos | B3: =+HLOOKUP(B1,[7]proyeccion_pob_raw!$A$200:$AF$201,2) -> 5006017 | C3: =+HLOOKUP(C1,[7]proyeccion_pob_raw!$A$200:$AF$201,2) -> 5110778 | D3: =+HLOOKUP(D1,[7]proyeccion_pob_raw!$A$200:$AF$201,2) -> 5221132 | E3: =+HLOOKUP(E1,[7]proyeccion_pob_raw!$A$200:$AF$201,2) -> 5336469 | F3: =+HLOOKUP(F1,[7]proyeccion_pob_raw!$A$200:$AF$201,2) -> 5456063 | G3: =+HLOOKUP(G1,[7]proyeccion_pob_raw!$A$200:$AF$201,2) -> 5579286 | H3: =+HLOOKUP(H1,[7]proyeccion_pob_raw!$A$200:$AF$201,2) -> 5705593 | I3: =+HLOOKUP(I1,[7]proyeccion_pob_raw!$A$200:$AF$201,2) -> 5834557 | ... Q3: =+HLOOKUP(Q1,[7]proyeccion_pob_raw!$A$200:$AF$201,2) -> 6881509 | R3: =+HLOOKUP(R$1,proyeccion_pob!$A$1:$AF$105,105) -> 5922327 | S3: =+HLOOKUP(S$1,proyeccion_pob!$A$1:$AF$105,105) -> 6031328 | T3: =+HLOOKUP(T$1,proyeccion_pob!$A$1:$AF$105,105) -> 6142648 | U3: =+HLOOKUP(U$1,proyeccion_pob!$A$1:$AF$105,105) -> 6255112 | V3: =+HLOOKUP(V$1,proyeccion_pob!$A$1:$AF$105,105) -> 6367718 | W3: =+HLOOKUP(W$1,proyeccion_pob!$A$1:$AF$105,105) -> 6480544 | X3: =+HLOOKUP(X$1,proyeccion_pob!$A$1:$AF$105,105) -> 6594032 | Y3: =+HLOOKUP(Y$1,proyeccion_pob!$A$1:$AF$105,105) -> 6709837 | ... AF3: =+HLOOKUP(AF$1,proyeccion_pob!$A$1:$AF$105,105) -> 7789606
A4: activos | B4: =+HLOOKUP(B1,[7]proyeccion_pob!$A$1:$AF$105,104) -> 23176847 | C4: =+HLOOKUP(C1,[7]proyeccion_pob!$A$1:$AF$105,104) -> 23513599 | D4: =+HLOOKUP(D1,[7]proyeccion_pob!$A$1:$AF$105,104) -> 23848008 | E4: =+HLOOKUP(E1,[7]proyeccion_pob!$A$1:$AF$105,104) -> 24178554 | F4: =+HLOOKUP(F1,[7]proyeccion_pob!$A$1:$AF$105,104) -> 24503741 | G4: =+HLOOKUP(G1,[7]proyeccion_pob!$A$1:$AF$105,104) -> 24822256 | H4: =+HLOOKUP(H1,[7]proyeccion_pob!$A$1:$AF$105,104) -> 25132656 | I4: =+HLOOKUP(I1,[7]proyeccion_pob!$A$1:$AF$105,104) -> 25434320 | ... Q4: =+HLOOKUP(Q1,[7]proyeccion_pob!$A$1:$AF$105,104) -> 28067225 | R4: =+HLOOKUP(R$1,proyeccion_pob!$A$1:$AF$105,104) -> 28334130 | S4: =+HLOOKUP(S$1,proyeccion_pob!$A$1:$AF$105,104) -> 28593757 | T4: =+HLOOKUP(T$1,proyeccion_pob!$A$1:$AF$105,104) -> 28861032 | U4: =+HLOOKUP(U$1,proyeccion_pob!$A$1:$AF$105,104) -> 29139313 | V4: =+HLOOKUP(V$1,proyeccion_pob!$A$1:$AF$105,104) -> 29415773 | W4: =+HLOOKUP(W$1,proyeccion_pob!$A$1:$AF$105,104) -> 29683894 | X4: =+HLOOKUP(X$1,proyeccion_pob!$A$1:$AF$105,104) -> 29939844 | Y4: =+HLOOKUP(Y$1,proyeccion_pob!$A$1:$AF$105,104) -> 30187462 | ... AF4: =+HLOOKUP(AF$1,proyeccion_pob!$A$1:$AF$105,104) -> 30992481
A5: prop_trabajadores | B5: =+B11/B4 -> 0.63532025 | C5: =+C11/C4 -> 0.66017949 | D5: =+D11/D4 -> 0.66849911 | E5: =+E11/E4 -> 0.67820344 | F5: =+F11/F4 -> 0.67272737 | G5: =+G11/G4 -> 0.66331023 | H5: =+H11/H4 -> 0.66991368 | I5: =+I11/I4 -> 0.68800063 | ... Q5: =+Q11/Q4 -> 0.64920503 | R5: =+constantes!$B$2 -> 0.6569162 | S5: =+constantes!$B$2 -> 0.6569162 | T5: =+constantes!$B$2 -> 0.6569162 | U5: =+constantes!$B$2 -> 0.6569162 | V5: =+constantes!$B$2 -> 0.6569162 | W5: =+constantes!$B$2 -> 0.6569162 | X5: =+constantes!$B$2 -> 0.6569162 | Y5: =+constantes!$B$2 -> 0.6569162 | ... AF5: =+constantes!$B$2 -> 0.6569162
A6: %informalidad | B6: =+VLOOKUP(B1,[7]informalidad!$A$1:$B$36,2) -> 0.43 | C6: =+VLOOKUP(C1,[7]informalidad!$A$1:$B$36,2) -> 0.43 | D6: =+VLOOKUP(D1,[7]informalidad!$A$1:$B$36,2) -> 0.43 | E6: =+VLOOKUP(E1,[7]informalidad!$A$1:$B$36,2) -> 0.43 | F6: =+VLOOKUP(F1,[7]informalidad!$A$1:$B$36,2) -> 0.42 | G6: =+VLOOKUP(G1,[7]informalidad!$A$1:$B$36,2) -> 0.41 | H6: =+VLOOKUP(H1,[7]informalidad!$A$1:$B$36,2) -> 0.42 | I6: =+VLOOKUP(I1,[7]informalidad!$A$1:$B$36,2) -> 0.43 | ... Q6: =+VLOOKUP(Q1,[7]informalidad!$A$1:$B$36,2) -> 0.429 | R6: =constantes!B17+(HLOOKUP(R1,vector_shock_infor_1!$A$1:$O$2,2)/100) -> 0.40243455 | S6: =+R6+(HLOOKUP(S1,vector_shock_infor_1!$A$1:$O$2,2)/100) -> 0.383279 | T6: =+S6+(HLOOKUP(T1,vector_shock_infor_1!$A$1:$O$2,2)/100) -> 0.39020415 | U6: =+T6+(HLOOKUP(U1,vector_shock_infor_1!$A$1:$O$2,2)/100) -> 0.34349853 | V6: =+U6+(HLOOKUP(V1,vector_shock_infor_1!$A$1:$O$2,2)/100) -> 0.35738335 | W6: =+V6+(HLOOKUP(W1,vector_shock_infor_1!$A$1:$O$2,2)/100) -> 0.37108905 | X6: =+W6+(HLOOKUP(X1,vector_shock_infor_1!$A$1:$O$2,2)/100) -> 0.36393295 | Y6: =+X6+(HLOOKUP(Y1,vector_shock_infor_1!$A$1:$O$2,2)/100) -> 0.41494783 | Z6: =+Y6+(HLOOKUP(Z1,vector_shock_infor_1!$A$1:$O$2,2)/100) -> 0.44490257 | ... AF6: =+AE6+(HLOOKUP(AF1,vector_shock_infor_1!$A$1:$O$2,2)/100) -> 0.49431875
A7: aportantes | B7: =+HLOOKUP(B1,[7]sipa_activos!$B$2:$AF$3,2) -> 8393090.4 | C7: =+HLOOKUP(C1,[7]sipa_activos!$B$2:$AF$3,2) -> 8848221.5 | D7: =+HLOOKUP(D1,[7]sipa_activos!$B$2:$AF$3,2) -> 9087152.2 | E7: =+HLOOKUP(E1,[7]sipa_activos!$B$2:$AF$3,2) -> 9346847.7 | F7: =+HLOOKUP(F1,[7]sipa_activos!$B$2:$AF$3,2) -> 9560915.6 | G7: =+HLOOKUP(G1,[7]sipa_activos!$B$2:$AF$3,2) -> 9714265.2 | H7: =+HLOOKUP(H1,[7]sipa_activos!$B$2:$AF$3,2) -> 9765291.8 | I7: =+HLOOKUP(I1,[7]sipa_activos!$B$2:$AF$3,2) -> 9974332 | ... Q7: =+HLOOKUP(Q1,[7]sipa_activos!$B$2:$AF$3,2) -> 10404410 | R7: =+R4*R5*(1-R6) -> 11122575 | S7: =+S4*S5*(1-S6) -> 11584304 | T7: =+T4*T5*(1-T6) -> 11561290 | U7: =+U4*U5*(1-U6) -> 12566808 | V7: =+V4*V5*(1-V6) -> 12417730 | W7: =+W4*W5*(1-W6) -> 12263657 | X7: =+X4*X5*(1-X6) -> 12510147 | Y7: =+Y4*Y5*(1-Y6) -> 11601955 | ... AF7: =+AF4*AF5*(1-AF6) -> 10295399
A8: aporte mensual promedio valuado en moneda uniforme mar 26 | B8: =+HLOOKUP(B1,[7]ndc_arg_prom!$A$11:$Q$20,10) -> 210700.64 | C8: =+HLOOKUP(C1,[7]ndc_arg_prom!$A$11:$Q$20,10) -> 243417.42 | D8: =+HLOOKUP(D1,[7]ndc_arg_prom!$A$11:$Q$20,10) -> 282617.68 | E8: =+HLOOKUP(E1,[7]ndc_arg_prom!$A$11:$Q$20,10) -> 309612.18 | F8: =+HLOOKUP(F1,[7]ndc_arg_prom!$A$11:$Q$20,10) -> 313440.56 | G8: =+HLOOKUP(G1,[7]ndc_arg_prom!$A$11:$Q$20,10) -> 354556.66 | H8: =+HLOOKUP(H1,[7]ndc_arg_prom!$A$11:$Q$20,10) -> 337749.84 | I8: =+HLOOKUP(I1,[7]ndc_arg_prom!$A$11:$Q$20,10) -> 342677.5 | ... Q8: =+HLOOKUP(Q1,[7]ndc_arg_prom!$A$11:$Q$20,10) -> 296699.47 | R8: =+$Q$8 -> 296699.47 | S8: =+$Q$8 -> 296699.47 | T8: =+$Q$8 -> 296699.47 | U8: =+$Q$8 -> 296699.47 | V8: =+$Q$8 -> 296699.47 | W8: =+$Q$8 -> 296699.47 | X8: =+$Q$8 -> 296699.47 | Y8: =+$Q$8 -> 296699.47 | ... AF8: =+$Q$8 -> 296699.47
A9: aportantes/activos | B9: =+B7/B4 -> 0.36213254 | C9: =+C7/C4 -> 0.37630231 | D9: =+D7/D4 -> 0.3810445 | E9: =+E7/E4 -> 0.38657596 | F9: =+F7/F4 -> 0.39018187 | G9: =+G7/G4 -> 0.39135303 | H9: =+H7/H4 -> 0.38854994 | I9: =+I7/I4 -> 0.39216036 | ... Q9: =+Q7/Q4 -> 0.37069607
A10: Total aportado | B10: =+B7*B8*13 -> 2.2989584e+13 | C10: =+C7*C8*13 -> 2.7999547e+13 | D10: =+D7*D8*13 -> 3.3386469e+13 | E10: =+E7*E8*13 -> 3.7620672e+13 | F10: =+F7*F8*13 -> 3.8958124e+13 | G10: =+G7*G8*13 -> 4.4775346e+13 | H10: =+H7*H8*13 -> 4.2876934e+13 | I10: =+I7*I8*13 -> 4.4433729e+13 | ... AF10: =+AF7*AF8*13 -> 3.9710311e+13
A11: trabajadores | B11: =+B7/(1-B6) -> 14724720 | C11: =+C7/(1-C6) -> 15523196 | D11: =+D7/(1-D6) -> 15942372 | E11: =+E7/(1-E6) -> 16397978 | F11: =+F7/(1-F6) -> 16484337 | G11: =+G7/(1-G6) -> 16464856 | H11: =+H7/(1-H6) -> 16836710 | I11: =+I7/(1-I6) -> 17498828 | ... Q11: =+Q7/(1-Q6) -> 18221384 | R11: =+R4*R5 -> 18613149 | S11: =+S4*S5 -> 18783702 | T11: =+T4*T5 -> 18959280 | U11: =+U4*U5 -> 19142087 | V11: =+V4*V5 -> 19323698 | W11: =+W4*W5 -> 19499831 | X11: =+X4*X5 -> 19667969 | Y11: =+Y4*Y5 -> 19830633 | ... AF11: =+AF4*AF5 -> 20359463
A12: JUBILACIONES
A13: Total jubilados | B13: =+HLOOKUP(B1,[7]sipa_pasivos!$B$19:$Z$21,2) -> 4224397.7 | C13: =+HLOOKUP(C1,[7]sipa_pasivos!$B$19:$Z$21,2) -> 4281335.2 | D13: =+HLOOKUP(D1,[7]sipa_pasivos!$B$19:$Z$21,2) -> 4309367.6 | E13: =+HLOOKUP(E1,[7]sipa_pasivos!$B$19:$Z$21,2) -> 4332215.8 | F13: =+HLOOKUP(F1,[7]sipa_pasivos!$B$19:$Z$21,2) -> 4357746.3 | G13: =+HLOOKUP(G1,[7]sipa_pasivos!$B$19:$Z$21,2) -> 4815401.4 | H13: =+HLOOKUP(H1,[7]sipa_pasivos!$B$19:$Z$21,2) -> 5111177.7 | I13: =+HLOOKUP(I1,[7]sipa_pasivos!$B$19:$Z$21,2) -> 5249685.9 | ... Q13: =+HLOOKUP(Q1,[7]sipa_pasivos!$B$19:$Z$21,2) -> 5779442.2 | R13: =+R3*R14 -> 4978720.9 | S13: =+S3*S14 -> 5070354.7 | T13: =+T3*T14 -> 5163938.1 | U13: =+U3*U14 -> 5258483.2 | V13: =+V3*V14 -> 5353147.6 | W13: =+W3*W14 -> 5447997 | X13: =+X3*X14 -> 5543402.9 | Y13: =+Y3*Y14 -> 5640756.7 | ... AF13: =+AF3*AF14 -> 6548485.8
A14: Alcance | B14: =+B13/B3 -> 0.84386403 | C14: =+C13/C3 -> 0.83770713 | D14: =+D13/D3 -> 0.82537036 | E14: =+E13/E3 -> 0.81181317 | F14: =+F13/F3 -> 0.79869795 | G14: =+G13/G3 -> 0.8630856 | H14: =+H13/H3 -> 0.89581883 | I14: =+I13/I3 -> 0.89975741 | ... Q14: =+Q13/Q3 -> 0.83985101 | R14: =+constantes!$B$3 -> 0.84066971 | S14: =+constantes!$B$3 -> 0.84066971 | T14: =+constantes!$B$3 -> 0.84066971 | U14: =+constantes!$B$3 -> 0.84066971 | V14: =+constantes!$B$3 -> 0.84066971 | W14: =+constantes!$B$3 -> 0.84066971 | X14: =+constantes!$B$3 -> 0.84066971 | Y14: =+constantes!$B$3 -> 0.84066971 | ... AF14: =+constantes!$B$3 -> 0.84066971
A15: prop_jub_morat | B15: =+VLOOKUP(B1,[7]sipa_pasivos_morat!$H$4:$J$30,3) -> 0.55036868 | C15: =+VLOOKUP(C1,[7]sipa_pasivos_morat!$H$4:$J$30,3) -> 0.56435596 | D15: =+VLOOKUP(D1,[7]sipa_pasivos_morat!$H$4:$J$30,3) -> 0.57304348 | E15: =+VLOOKUP(E1,[7]sipa_pasivos_morat!$H$4:$J$30,3) -> 0.57835601 | F15: =+VLOOKUP(F1,[7]sipa_pasivos_morat!$H$4:$J$30,3) -> 0.58264704 | G15: =+VLOOKUP(G1,[7]sipa_pasivos_morat!$H$4:$J$30,3) -> 0.6231629 | H15: =+VLOOKUP(H1,[7]sipa_pasivos_morat!$H$4:$J$30,3) -> 0.64430318 | I15: =+VLOOKUP(I1,[7]sipa_pasivos_morat!$H$4:$J$30,3) -> 0.6495998 | ... Q15: =+VLOOKUP(Q1,[7]sipa_pasivos_morat!$H$4:$J$30,3) -> 0.68551243 | R15: =+constantes!$B$7 -> 0.62919166 | S15: =+constantes!$B$7 -> 0.62919166 | T15: =+constantes!$B$7 -> 0.62919166 | U15: =+constantes!$B$7 -> 0.62919166 | V15: =+constantes!$B$7 -> 0.62919166 | W15: =+constantes!$B$7 -> 0.62919166 | X15: =+constantes!$B$7 -> 0.62919166 | Y15: =+constantes!$B$7 -> 0.62919166 | ... AF15: =+constantes!$B$7 -> 0.62919166
A16: Jubilados con morat | B16: =+B13*VLOOKUP(B1,[7]sipa_pasivos_morat!$H$4:$J$30,3) -> 2324976.2 | C16: =+C13*VLOOKUP(C1,[7]sipa_pasivos_morat!$H$4:$J$30,3) -> 2416197 | D16: =+D13*VLOOKUP(D1,[7]sipa_pasivos_morat!$H$4:$J$30,3) -> 2469455 | E16: =+E13*VLOOKUP(E1,[7]sipa_pasivos_morat!$H$4:$J$30,3) -> 2505563.1 | F16: =+F13*VLOOKUP(F1,[7]sipa_pasivos_morat!$H$4:$J$30,3) -> 2539028 | G16: =+G13*VLOOKUP(G1,[7]sipa_pasivos_morat!$H$4:$J$30,3) -> 3000779.5 | H16: =+H13*VLOOKUP(H1,[7]sipa_pasivos_morat!$H$4:$J$30,3) -> 3293148 | I16: =+I13*VLOOKUP(I1,[7]sipa_pasivos_morat!$H$4:$J$30,3) -> 3410194.9 | ... P16: =+P13*VLOOKUP(P1,[7]sipa_pasivos_morat!$H$4:$J$30,3) -> 3838112.6 | Q16: =+Q13*Q15 -> 3961879.5 | R16: =+R13*R15 -> 3132569.6 | S16: =+S13*S15 -> 3190224.9 | T16: =+T13*T15 -> 3249106.8 | U16: =+U13*U15 -> 3308593.7 | V16: =+V13*V15 -> 3368155.8 | W16: =+W13*W15 -> 3427834.3 | X16: =+X13*X15 -> 3487862.9 | ... AF16: =+AF13*AF15 -> 4120252.6
A17: Jubilados sin morat | B17: =+B13-B16 -> 1899421.5 | C17: =+C13-C16 -> 1865138.2 | D17: =+D13-D16 -> 1839912.6 | E17: =+E13-E16 -> 1826652.8 | F17: =+F13-F16 -> 1818718.3 | G17: =+G13-G16 -> 1814621.9 | H17: =+H13-H16 -> 1818029.7 | I17: =+I13-I16 -> 1839491 | ... AF17: =+AF13-AF16 -> 2428233.2
A18: desc_jub_morat | B18: =+constantes!$B$9 -> -0.44399456 | C18: =+constantes!$B$9 -> -0.44399456 | D18: =+constantes!$B$9 -> -0.44399456 | E18: =+constantes!$B$9 -> -0.44399456 | F18: =+constantes!$B$9 -> -0.44399456 | G18: =+constantes!$B$9 -> -0.44399456 | H18: =+constantes!$B$9 -> -0.44399456 | I18: =+constantes!$B$9 -> -0.44399456 | ... AF18: =+constantes!$B$9 -> -0.44399456
A19: Jubilación NDC | B19: =+[7]ndc_arg_prom!$B$29 -> 695343.7 | C19: =+[7]ndc_arg_prom!$B$29 -> 695343.7 | D19: =+[7]ndc_arg_prom!$B$29 -> 695343.7 | E19: =+[7]ndc_arg_prom!$B$29 -> 695343.7 | F19: =+[7]ndc_arg_prom!$B$29 -> 695343.7 | G19: =+[7]ndc_arg_prom!$B$29 -> 695343.7 | H19: =+[7]ndc_arg_prom!$B$29 -> 695343.7 | I19: =+[7]ndc_arg_prom!$B$29 -> 695343.7 | ... Q19: =+[7]ndc_arg_prom!$B$29 -> 695343.7 | R19: =+Q19 -> 695343.7 | S19: =+R19 -> 695343.7 | T19: =+S19 -> 695343.7 | U19: =+T19 -> 695343.7 | V19: =+U19 -> 695343.7 | W19: =+V19 -> 695343.7 | X19: =+W19 -> 695343.7 | Y19: =+X19 -> 695343.7 | ... AF19: =+AE19 -> 695343.7
A20: Jubilación NDC con morat | B20: =+B19*(1+B18) -> 386614.88 | C20: =+C19*(1+C18) -> 386614.88 | D20: =+D19*(1+D18) -> 386614.88 | E20: =+E19*(1+E18) -> 386614.88 | F20: =+F19*(1+F18) -> 386614.88 | G20: =+G19*(1+G18) -> 386614.88 | H20: =+H19*(1+H18) -> 386614.88 | I20: =+I19*(1+I18) -> 386614.88 | ... AF20: =+AF19*(1+AF18) -> 386614.88
A21: Total beneficios jub | R21: =+(R16*R20+R17*R19)*12 -> 2.9937692e+13
A22: PENSIONES | R22: =+R13*R19*(R15*(1+R18)+1*(1-R15))*12 -> 2.9937692e+13
A23: prop_pensionados | B23: =+B25/B2 -> 0.0064723274 | C23: =+C25/C2 -> 0.0064855125 | D23: =+D25/D2 -> 0.0064817641 | E23: =+E25/E2 -> 0.0064888961 | F23: =+F25/F2 -> 0.0064741068 | G23: =+G25/G2 -> 0.0064548013 | H23: =+H25/H2 -> 0.0064703476 | I23: =+I25/I2 -> 0.0065175946 | ... Q23: =+Q25/Q2 -> 0.0065266517 | R23: =+constantes!$B$4 -> 0.035520399 | S23: =+constantes!$B$4 -> 0.035520399 | T23: =+constantes!$B$4 -> 0.035520399 | U23: =+constantes!$B$4 -> 0.035520399 | V23: =+constantes!$B$4 -> 0.035520399 | W23: =+constantes!$B$4 -> 0.035520399 | X23: =+constantes!$B$4 -> 0.035520399 | Y23: =+constantes!$B$4 -> 0.035520399 | ... AF23: =+constantes!$B$4 -> 0.035520399
A24: prop_pensionados_menores | B24: =+constantes!$B$5 -> 0.18234941 | C24: =+constantes!$B$5 -> 0.18234941 | D24: =+constantes!$B$5 -> 0.18234941 | E24: =+constantes!$B$5 -> 0.18234941 | F24: =+constantes!$B$5 -> 0.18234941 | G24: =+constantes!$B$5 -> 0.18234941 | H24: =+constantes!$B$5 -> 0.18234941 | I24: =+constantes!$B$5 -> 0.18234941 | ... AF24: =+constantes!$B$5 -> 0.18234941
A25: pensionados_menores | B25: =+HLOOKUP(B1,[7]sipa_pasivos!$B$19:$Z$21,3)*B24 -> 263996.22 | C25: =+HLOOKUP(C1,[7]sipa_pasivos!$B$19:$Z$21,3)*C24 -> 267601.91 | D25: =+HLOOKUP(D1,[7]sipa_pasivos!$B$19:$Z$21,3)*D24 -> 270505.22 | E25: =+HLOOKUP(E1,[7]sipa_pasivos!$B$19:$Z$21,3)*E24 -> 273850.46 | F25: =+HLOOKUP(F1,[7]sipa_pasivos!$B$19:$Z$21,3)*F24 -> 276246.9 | G25: =+HLOOKUP(G1,[7]sipa_pasivos!$B$19:$Z$21,3)*G24 -> 278408.27 | H25: =+HLOOKUP(H1,[7]sipa_pasivos!$B$19:$Z$21,3)*H24 -> 282044.83 | I25: =+HLOOKUP(I1,[7]sipa_pasivos!$B$19:$Z$21,3)*I24 -> 287066.22 | ... Q25: =+HLOOKUP(Q1,[7]sipa_pasivos!$B$19:$Z$21,3)*Q24 -> 302752.43 | R25: =+R2*R23*R24 -> 300970.49 | S25: =+S2*S23*S24 -> 301445.8 | T25: =+T2*T23*T24 -> 301895.72 | U25: =+U2*U23*U24 -> 302332.7 | V25: =+V2*V23*V24 -> 302769.2 | W25: =+W2*W23*W24 -> 303221.78 | X25: =+X2*X23*X24 -> 303691.2 | Y25: =+Y2*Y23*Y24 -> 304177.41 | ... AF25: =+AF2*AF23*AF24 -> 307754.81
A26: propor_pen_morat | B26: =+VLOOKUP(B1,[7]sipa_pasivos_morat!$H$4:$J$30,2) -> 0.068140138 | C26: =+VLOOKUP(C1,[7]sipa_pasivos_morat!$H$4:$J$30,2) -> 0.090319611 | D26: =+VLOOKUP(D1,[7]sipa_pasivos_morat!$H$4:$J$30,2) -> 0.11107752 | E26: =+VLOOKUP(E1,[7]sipa_pasivos_morat!$H$4:$J$30,2) -> 0.12767256 | F26: =+VLOOKUP(F1,[7]sipa_pasivos_morat!$H$4:$J$30,2) -> 0.14253696 | G26: =+VLOOKUP(G1,[7]sipa_pasivos_morat!$H$4:$J$30,2) -> 0.15754727 | H26: =+VLOOKUP(H1,[7]sipa_pasivos_morat!$H$4:$J$30,2) -> 0.17817899 | I26: =+VLOOKUP(I1,[7]sipa_pasivos_morat!$H$4:$J$30,2) -> 0.20249259 | ... Q26: =+VLOOKUP(Q1,[7]sipa_pasivos_morat!$H$4:$J$30,2) -> 0.32724048 | R26: =+constantes!$B$6 -> 0.20660613 | S26: =+constantes!$B$6 -> 0.20660613 | T26: =+constantes!$B$6 -> 0.20660613 | U26: =+constantes!$B$6 -> 0.20660613 | V26: =+constantes!$B$6 -> 0.20660613 | W26: =+constantes!$B$6 -> 0.20660613 | X26: =+constantes!$B$6 -> 0.20660613 | Y26: =+constantes!$B$6 -> 0.20660613 | ... AF26: =+constantes!$B$6 -> 0.20660613
A27: # menores 65 con morat | B27: =+B25*VLOOKUP(B1,[7]sipa_pasivos_morat!$H$4:$J$30,2) -> 17988.739 | C27: =+C25*VLOOKUP(C1,[7]sipa_pasivos_morat!$H$4:$J$30,2) -> 24169.7 | D27: =+D25*VLOOKUP(D1,[7]sipa_pasivos_morat!$H$4:$J$30,2) -> 30047.05 | E27: =+E25*VLOOKUP(E1,[7]sipa_pasivos_morat!$H$4:$J$30,2) -> 34963.19 | F27: =+F25*VLOOKUP(F1,[7]sipa_pasivos_morat!$H$4:$J$30,2) -> 39375.392 | G27: =+G25*VLOOKUP(G1,[7]sipa_pasivos_morat!$H$4:$J$30,2) -> 43862.464 | H27: =+H25*VLOOKUP(H1,[7]sipa_pasivos_morat!$H$4:$J$30,2) -> 50254.465 | I27: =+I25*VLOOKUP(I1,[7]sipa_pasivos_morat!$H$4:$J$30,2) -> 58128.783 | ... Q27: =+Q25*VLOOKUP(Q1,[7]sipa_pasivos_morat!$H$4:$J$30,2) -> 99072.851 | R27: =+R25*R26 -> 62182.349 | S27: =+S25*S26 -> 62280.551 | T27: =+T25*T26 -> 62373.506 | U27: =+U25*U26 -> 62463.79 | V27: =+V25*V26 -> 62553.972 | W27: =+W25*W26 -> 62647.48 | X27: =+X25*X26 -> 62744.464 | Y27: =+Y25*Y26 -> 62844.918 | ... AF27: =+AF25*AF26 -> 63584.031
A28: # menores 65 sin morat | B28: =+B25-B27 -> 246007.48 | C28: =+C25-C27 -> 243432.21 | D28: =+D25-D27 -> 240458.17 | E28: =+E25-E27 -> 238887.27 | F28: =+F25-F27 -> 236871.51 | G28: =+G25-G27 -> 234545.81 | H28: =+H25-H27 -> 231790.37 | I28: =+I25-I27 -> 228937.44 | ... AF28: =+AF25-AF27 -> 244170.78
A29: desc_pen_morat | B29: =+constantes!$B$8 -> -0.78529601 | C29: =+constantes!$B$8 -> -0.78529601 | D29: =+constantes!$B$8 -> -0.78529601 | E29: =+constantes!$B$8 -> -0.78529601 | F29: =+constantes!$B$8 -> -0.78529601 | G29: =+constantes!$B$8 -> -0.78529601 | H29: =+constantes!$B$8 -> -0.78529601 | I29: =+constantes!$B$8 -> -0.78529601 | ... AF29: =+constantes!$B$8 -> -0.78529601
A30: Pensión NDC sin morat | B30: =+B19*0.7 -> 486740.59 | C30: =+C19*0.7 -> 486740.59 | D30: =+D19*0.7 -> 486740.59 | E30: =+E19*0.7 -> 486740.59 | F30: =+F19*0.7 -> 486740.59 | G30: =+G19*0.7 -> 486740.59 | H30: =+H19*0.7 -> 486740.59 | I30: =+I19*0.7 -> 486740.59 | ... AF30: =+AF19*0.7 -> 486740.59
A31: Pensión NDC con morat | B31: =+B30*(1+B29) -> 104505.15 | C31: =+C30*(1+C29) -> 104505.15 | D31: =+D30*(1+D29) -> 104505.15 | E31: =+E30*(1+E29) -> 104505.15 | F31: =+F30*(1+F29) -> 104505.15 | G31: =+G30*(1+G29) -> 104505.15 | H31: =+H30*(1+H29) -> 104505.15 | I31: =+I30*(1+I29) -> 104505.15 | ... AF31: =+AF30*(1+AF29) -> 104505.15
A32: Total beneficios pen | R32: =+(R27*R31+R28*R30)*12 -> 1.4727151e+12
A33: Total beneficios | B33: =(B16*B20+B17*B19+B27*B31+B28*B30)*12 -> 2.8094915e+13 | C33: =(C16*C20+C17*C19+C27*C31+C28*C30)*12 -> 2.8224768e+13 | D33: =(D16*D20+D17*D19+D27*D31+D28*D30)*12 -> 2.8251366e+13 | E33: =(E16*E20+E17*E19+E27*E31+E28*E30)*12 -> 2.8305233e+13 | F33: =(F16*F20+F17*F19+F27*F31+F28*F30)*12 -> 2.8388043e+13 | G33: =(G16*G20+G17*G19+G27*G31+G28*G30)*12 -> 3.0488145e+13 | H33: =(H16*H20+H17*H19+H27*H31+H28*H30)*12 -> 3.186491e+13 | I33: =(I16*I20+I17*I19+I27*I31+I28*I30)*12 -> 3.2580222e+13 | ... AF33: =(AF16*AF20+AF17*AF19+AF27*AF31+AF28*AF30)*12 -> 4.0882804e+13
A35: Resultado prev inicial | B35: =+B10-B33 -> -5.1053309e+12 | C35: =+C10-C33 -> -2.2522112e+11 | D35: =+D10-D33 -> 5.1351028e+12 | E35: =+E10-E33 -> 9.3154393e+12 | F35: =+F10-F33 -> 1.0570081e+13 | G35: =+G10-G33 -> 1.4287201e+13 | H35: =+H10-H33 -> 1.1012025e+13 | I35: =+I10-I33 -> 1.1853507e+13 | ... AF35: =+AF10-AF33 -> -1.1724927e+12
A36: Fondo Acumulado inicio | B36: =141921338041*('[7]ipc_10-26'!E196/'[7]ipc_10-26'!E3) -> 5.15785e+13 | C36: =+B39*(1+$B$60) -> 4.7054083e+13 | D36: =+C39*(1+$B$60) -> 4.7414223e+13 | E36: =+D39*(1+$B$60) -> 5.3206192e+13 | F36: =+E39*(1+$B$60) -> 6.3303152e+13 | G36: =+F39*(1+$B$60) -> 7.4796648e+13 | H36: =+G39*(1+$B$60) -> 9.0197398e+13 | I36: =+H39*(1+$B$60) -> 1.0247454e+14 | J36: =+I39*(1+$B$60) -> 1.1575715e+14 | ... AF36: =+AE39*(1+$B$60) -> 3.0339719e+14
A37: Intereses del fondo | C37: =+B39*$B$60 -> 5.8091461e+11 | D37: =+C39*$B$60 -> 5.8536078e+11 | E37: =+D39*$B$60 -> 6.5686657e+11 | F37: =+E39*$B$60 -> 7.815204e+11 | G37: =+F39*$B$60 -> 9.2341541e+11 | H37: =+G39*$B$60 -> 1.1135481e+12 | I37: =+H39*$B$60 -> 1.2651178e+12 | J37: =+I39*$B$60 -> 1.4291006e+12 | ... AF37: =+AE39*$B$60 -> 3.7456444e+12
A38: Pagado con fondo | B38: =+IF(B35<0,(-1)*B35,0) -> 5.1053309e+12 | C38: =+IF(C35<0,(-1)*C35,0) -> 2.2522112e+11 | D38: =+IF(D35<0,(-1)*D35,0) -> 0 | E38: =+IF(E35<0,(-1)*E35,0) -> 0 | F38: =+IF(F35<0,(-1)*F35,0) -> 0 | G38: =+IF(G35<0,(-1)*G35,0) -> 0 | H38: =+IF(H35<0,(-1)*H35,0) -> 0 | I38: =+IF(I35<0,(-1)*I35,0) -> 0 | ... AF38: =+IF(AF35<0,(-1)*AF35,0) -> 1.1724927e+12
A39: Fondo Acumulado final | B39: =+B36-B38+IF(B35>0,B35,0) -> 4.6473169e+13 | C39: =+C36-C38+IF(C35>0,C35,0) -> 4.6828862e+13 | D39: =+D36-D38+IF(D35>0,D35,0) -> 5.2549326e+13 | E39: =+E36-E38+IF(E35>0,E35,0) -> 6.2521632e+13 | F39: =+F36-F38+IF(F35>0,F35,0) -> 7.3873233e+13 | G39: =+G36-G38+IF(G35>0,G35,0) -> 8.908385e+13 | H39: =+H36-H38+IF(H35>0,H35,0) -> 1.0120942e+14 | I39: =+I36-I38+IF(I35>0,I35,0) -> 1.1432805e+14 | ... AF39: =+AF36-AF38+IF(AF35>0,AF35,0) -> 3.022247e+14
A42: Fondo reserva | B42: =+B39 -> 4.6473169e+13 | C42: =+C39 -> 4.6828862e+13 | D42: =+D39 -> 5.2549326e+13 | E42: =+E39 -> 6.2521632e+13 | F42: =+F39 -> 7.3873233e+13 | G42: =+G39 -> 8.908385e+13 | H42: =+H39 -> 1.0120942e+14 | I42: =+I39 -> 1.1432805e+14 | ... AF42: =+AF39 -> 3.022247e+14
A43: TD | B43: 30 | C43: 30 | D43: 30 | E43: 30 | F43: 30 | G43: 30 | H43: 30 | I43: 30 | J43: 30 | K43: 30 | L43: 30 | M43: 30 | N43: 30 | O43: 30 | P43: 30 | Q43: 30 | R43: 30 | S43: 30 | T43: 30 | U43: 30 | V43: 30 | W43: 30 | X43: 30 | Y43: 30 | Z43: 30 | AA43: 30 | AB43: 30 | AC43: 30 | AD43: 30 | AE43: 30 | AF43: 30
...

Sheet vector_shock_infor_1
A1: 2026 | B1: 2027 | C1: 2028 | D1: 2029 | E1: 2030 | F1: 2031 | G1: 2032 | H1: 2033 | I1: 2034 | J1: 2035 | K1: 2036 | L1: 2037 | M1: 2038 | N1: 2039 | O1: 2040
A2: -1.469045 | B2: -1.915555 | C2: 0.692515 | D2: -4.670562 | E2: 1.388482 | F2: 1.37057 | G2: -0.71561 | H2: 5.101488 | I2: 2.995474 | J2: 2.685504 | K2: -4.334693 | L2: -0.199716 | M2: 1.610026 | N2: 3.404093 | O2: 1.776404
